Workbook
Name ImpactRange: 'Peta Risiko'!$D$36:$D$40
Name likelihood: [1]data!$C$82:$C$87
Name likelihood: [1]data!$C$82:$C$87
Name likelihood: [1]data!$C$82:$C$87
Name likelihood: [1]data!$C$82:$C$87
Name likelihood: [1]data!$C$82:$C$87
Name LikelihoodRange: 'Peta Risiko'!$D$29:$D$33
Name Opsi: [1]data!$E$23:$E$27
Name Opsi: [1]data!$E$23:$E$27
Name Opsi: [1]data!$E$23:$E$27
Name Opsi: [1]data!$E$23:$E$27
Name Opsi: [1]data!$E$23:$E$27
Name RangeDampak: 'Peta Risiko'!$F$5:$J$5
Name RangeKemungkinan: 'Peta Risiko'!$E$6:$E$10
Name RangeLikelihood: 'Peta Risiko'!$D$29:$I$33
Name RiskLevel: 'Peta Risiko'!$F$15:$J$19
Name RiskMatrix: 'Peta Risiko'!$F$6:$J$10
Name saa: [2]vulnerabilities!$A$2:$A$200
Name severity: [1]data!$F$83:$F$87
Name severity: [1]data!$F$83:$F$87
Name severity: [1]data!$F$83:$F$87
Name severity: [1]data!$F$83:$F$87
Name severity: [1]data!$F$83:$F$87
Name threat1: [1]threat!$A$2:$A$132
Name threat1: [1]threat!$A$2:$A$132
Name threat1: [1]threat!$A$2:$A$132
Name threat1: [1]threat!$A$2:$A$132
Name threat1: [1]threat!$A$2:$A$132
Name threat1: [3]threat!$A$2:$A$132
Name Vulnerability: [1]vulnerabilities!$A$2:$A$200
Name Vulnerability: [1]vulnerabilities!$A$2:$A$200
Name Vulnerability: [1]vulnerabilities!$A$2:$A$200
Name Vulnerability: [1]vulnerabilities!$A$2:$A$200
Name Vulnerability: [1]vulnerabilities!$A$2:$A$200

Sheet Ringkasan
B1: LAPORAN PENILAIAN RISIKO KEAMANAN SIBER PEMERINTAH DAERAH XXX | G1: No Dokumen | H1: :
G2: Revisi | H2: :
G3: Tanggal | H3: :
G4: Jenis Dok | H4: : Internal
A7: RISK ACCEPTABLE PROFILE
A8: KLASIFIKASI ASET | B8: JUMLAH RISIKO | C8: INHERENT RISK | F8: RESIDUAL RISK
C9: Number of Acceptable Risk | D9: Number of Unacceptable Risk | E9: % Acceptable of Inherent Risk | F9: Number of Acceptable Risk | G9: Number of Unacceptable Risk | H9: % Acceptable of Residual Risk
A10: Data dan Informasi | B10: ='Data dan Informasi'!AI12 -> 2 | C10: ='Data dan Informasi'!AG12 -> 1 | D10: ='Data dan Informasi'!AH12 -> 1 | E10: =C10/B10*100% -> 0.5 | F10: ='Data dan Informasi'!AB12 -> 1 | G10: ='Data dan Informasi'!AC12 -> 0 | H10: =F10/B10*100% -> 0.5
A11: Perangkat Lunak | B11: ='Perangkat Lunak'!AI12 -> 2 | C11: ='Perangkat Lunak'!AG12 -> 1 | D11: ='Perangkat Lunak'!AH12 -> 1 | E11: =C11/D11*100% -> 1 | F11: ='Perangkat Lunak'!AB12 -> 0 | G11: ='Perangkat Lunak'!AC12 -> 1 | H11: =F11/B11*100% -> 0
A12: Perangkat Keras | B12: ='Perangkat Keras'!AI12 -> 2 | C12: ='Perangkat Keras'!AG12 -> 1 | D12: ='Perangkat Keras'!AH12 -> 1 | E12: =C12/D12*100% -> 1 | F12: ='Perangkat Keras'!AB12 -> 1 | G12: ='Perangkat Keras'!AC12 -> 0 | H12: =F12/B12*100% -> 0.5
A13: Sarana Pendukung | B13: ='Sarana Pendukung'!AI12 -> 2 | C13: ='Sarana Pendukung'!AG12 -> 1 | D13: ='Sarana Pendukung'!AH12 -> 1 | E13: =C13/D13*100% -> 1 | F13: ='Sarana Pendukung'!AB12 -> 1 | G13: ='Sarana Pendukung'!AC12 -> 0 | H13: =F13/B13*100% -> 0.5
A14: SDM & Pihak Ketiga | B14: ='Sarana Pendukung'!AI12 -> 2 | C14: ='Sarana Pendukung'!AG12 -> 1 | D14: ='Sarana Pendukung'!AH12 -> 1 | E14: =C14/D14*100% -> 1 | F14: ='Sarana Pendukung'!AB12 -> 1 | G14: ='Sarana Pendukung'!AC12 -> 0 | H14: =F14/B14*100% -> 0.5
E33: Disiapkan oleh, | G33: Disetujui oleh,

Sheet Data dan Informasi
D2: REGISTER RISIKO KEAMANAN INFORMASI (ASET: DATA & INFORMASI) | V2: Revisi | Y2: Tanggal: | Z2: Dokumen:
A4: Risk No | B4: Jenis Risiko | C4: Identifikasi Resiko | I4: Kontrol Saat Ini | J4: Nilai Resiko Bawaan (Inherent Risk) | N4: EVALUASI RISIKO | P4: RENCANA PENANGANAN RISIKO | V4: Residual Risk | Z4: Rencana Kontrol Tambahan | AA4: Risk Owner
C5: Aset | D5: Ancaman/Kejadian | E5: Kerawanan/Kelemahan/ Penyebab | F5: Kategori | G5: Dampak | H5: Area Dampak | N5: Keputusan Penanganan Risiko | O5: Prioritas Risiko | P5: Opsi Penanganan | Q5: Rencana Aksi Penanganan Risiko | R5: Keluaran | S5: Target/Jadwal Implementasi | T5: Penanggung Jawab | U5: Apakah Terdapat Residual Risk | V5: Dampak | W5: Kemungkinan | X5: RR | Y5: Status | AB5: Residual
J6: Dampak | K6: Kemungkinan | L6: IR | M6: Level Risiko | AB6: Acc | AC6: Not | AF6: Status Inherent Risk | AG6: Acc | AH6: Not | AI6: sum
A7: DI-001 | B7: Negatif | C7: Data Hasil Audit | D7: Kebocoran data | E7: Dokumen tidak disimpan dengan baik | F7: Kesalahan Pengelolaan Data dan Informasi Terbatas | G7: Hasil audit disalahgunakan oleh pihak yang tidak berwenang | H7: Hukum dan Regulasi | I7: Belum ada | J7: Kurang Signifikan | K7: Jarang Terjadi | L7: =INDEX(RiskMatrix,MATCH(K7,RangeKemungkinan,0),MATCH(J7,RangeDampak,0)) -> 7 | M7: =INDEX(RiskLevel,MATCH(K7,RangeKemungkinan,0),MATCH(J7,RangeDampak,0)) -> Rendah | N7: Ya | O7: 1 | P7: Mitigasi Risiko | Q7: Menerapkan enkripsi/password pada data hasil audit elektronik | R7: Data Hasil Audit yang terenkripsi | S7: Desember 2025 | T7: Kepala Bidang Persandian | U7: Tidak | AA7: Inspektur | AB7: =IF(Y7="Acceptable",1,0) -> 0 | AC7: =IF(Y7="Not Acceptable",1,0) -> 0 | AF7: =IF(ISNUMBER(L7),IF(L7>=11,"Not Acceptable","Acceptable"),"N/A") -> Acceptable | AG7: =IF(AF7="Acceptable",1,0) -> 1 | AH7: =IF(AF7="Not Acceptable",1,0) -> 0
A8: DI-002 | B8: Negatif | C8: Dokumen Data Statistik Sektoral | D8: Kebocoran data pribadi | E8: Belum ada kebijakan pengaturan data pribadi/ data statistik | F8: Pencurian Data Pribadi | G8: Data pribadi pegawai disalahgunakan oleh pihak yang tidak berwenang | H8: Hukum dan Regulasi | I8: Belum ada | J8: Signifikan | K8: Jarang Terjadi | L8: =INDEX(RiskMatrix,MATCH(K8,RangeKemungkinan,0),MATCH(J8,RangeDampak,0)) -> 13 | M8: =INDEX(RiskLevel,MATCH(K8,RangeKemungkinan,0),MATCH(J8,RangeDampak,0)) -> Sedang | N8: Ya | P8: Mitigasi Risiko | Q8: Menyusun Kebijakan Data Pribadi | R8: Kebijakan Data Pribadi | S8: Oktober 2025 | T8: Kepala Bidang Persandian | U8: Ya | V8: Kurang Signifikan | W8: Jarang Terjadi | X8: =IF(U8="Ya",(INDEX(RiskMatrix,MATCH(W8,RangeKemungkinan,0),MATCH(V8,RangeDampak,0))),"N/A") -> 7 | Y8: =IF(ISNUMBER(X8),IF(X8>=11,"Not Acceptable","Acceptable"),"N/A") -> Acceptable | Z8: - | AA8: Diskominfo | AB8: =IF(Y8="Acceptable",1,0) -> 1 | AC8: =IF(Y8="Not Acceptable",1,0) -> 0 | AF8: =IF(ISNUMBER(L8),IF(L8>=11,"Not Acceptable","Acceptable"),"N/A") -> Not Acceptable | AG8: =IF(AF8="Acceptable",1,0) -> 0 | AH8: =IF(AF8="Not Acceptable",1,0) -> 1
A9: DI-003 | L9: =INDEX(RiskMatrix,MATCH(K9,RangeKemungkinan,0),MATCH(J9,RangeDampak,0)) -> #N/A | M9: =INDEX(RiskLevel,MATCH(K9,RangeKemungkinan,0),MATCH(J9,RangeDampak,0)) -> #N/A | X9: =IF(U9="Ya",(INDEX(RiskMatrix,MATCH(W9,RangeKemungkinan,0),MATCH(V9,RangeDampak,0))),"N/A") -> N/A | Y9: =IF(ISNUMBER(X9),IF(X9>=11,"Not Acceptable","Acceptable"),"N/A") -> N/A | AB9: =IF(Y9="Acceptable",1,0) -> 0 | AC9: =IF(Y9="Not Acceptable",1,0) -> 0 | AF9: =IF(ISNUMBER(L9),IF(L9>=11,"Not Acceptable","Acceptable"),"N/A") -> N/A | AG9: =IF(AF9="Acceptable",1,0) -> 0 | AH9: =IF(AF9="Not Acceptable",1,0) -> 0
A10: DI-004 | L10: =INDEX(RiskMatrix,MATCH(K10,RangeKemungkinan,0),MATCH(J10,RangeDampak,0)) -> #N/A | M10: =INDEX(RiskLevel,MATCH(K10,RangeKemungkinan,0),MATCH(J10,RangeDampak,0)) -> #N/A | X10: =IF(U10="Ya",(INDEX(RiskMatrix,MATCH(W10,RangeKemungkinan,0),MATCH(V10,RangeDampak,0))),"N/A") -> N/A | Y10: =IF(ISNUMBER(X10),IF(X10>=11,"Not Acceptable","Acceptable"),"N/A") -> N/A | AB10: =IF(Y10="Acceptable",1,0) -> 0 | AC10: =IF(Y10="Not Acceptable",1,0) -> 0 | AF10: =IF(ISNUMBER(L10),IF(L10>=11,"Not Acceptable","Acceptable"),"N/A") -> N/A | AG10: =IF(AF10="Acceptable",1,0) -> 0 | AH10: =IF(AF10="Not Acceptable",1,0) -> 0
A11: DI-005 | L11: =INDEX(RiskMatrix,MATCH(K11,RangeKemungkinan,0),MATCH(J11,RangeDampak,0)) -> #N/A | M11: =INDEX(RiskLevel,MATCH(K11,RangeKemungkinan,0),MATCH(J11,RangeDampak,0)) -> #N/A | X11: =IF(U11="Ya",(INDEX(RiskMatrix,MATCH(W11,RangeKemungkinan,0),MATCH(V11,RangeDampak,0))),"N/A") -> N/A | Y11: =IF(ISNUMBER(X11),IF(X11>=11,"Not Acceptable","Acceptable"),"N/A") -> N/A | AB11: =IF(Y11="Acceptable",1,0) -> 0 | AC11: =IF(Y11="Not Acceptable",1,0) -> 0 | AF11: =IF(ISNUMBER(L11),IF(L11>=11,"Not Acceptable","Acceptable"),"N/A") -> N/A | AG11: =IF(AF11="Acceptable",1,0) -> 0 | AH11: =IF(AF11="Not Acceptable",1,0) -> 0
AB12: =SUM(AB7:AB11) -> 1 | AC12: =SUM(AC7:AC11) -> 0 | AG12: =SUM(AG7:AG11) -> 1 | AH12: =SUM(AH7:AH11) -> 1 | AI12: =SUM(AG12:AH12) -> 2

Sheet Perangkat Lunak
D2: REGISTER RISIKO KEAMANAN INFORMASI (ASET: PERANGKAT LUNAK) | V2: Revisi | Y2: Tanggal: | Z2: Dokumen:
A4: Risk No | B4: Jenis Risiko | C4: Identifikasi Resiko | I4: Kontrol Saat Ini | J4: Nilai Resiko Bawaan (Inherent Risk) | N4: EVALUASI RISIKO | P4: RENCANA PENANGANAN RISIKO | V4: Residual Risk | Z4: Rencana Kontrol Tambahan | AA4: Risk Owner
C5: Aset | D5: Ancaman | E5: Kerawanan/Kelemahan | F5: Kategori | G5: Dampak | H5: Area Dampak | N5: Keputusan Penanganan Risiko | O5: Prioritas Risiko | P5: Opsi Penanganan | Q5: Rencana Aksi Penanganan Risiko | R5: Keluaran | S5: Target/Jadwal Implementasi | T5: Penanggung Jawab | U5: Apakah Terdapat Residual Risk | V5: Dampak | W5: Kemungkinan | X5: RR | Y5: Status | AB5: Residual
J6: Dampak | K6: Kemungkinan | L6: IR | M6: Level Risiko | AB6: Acc | AC6: Not | AF6: Status Inherent Risk | AG6: Acc | AH6: Not | AI6: sum
A7: PL-001 | B7: Negatif | C7: Aplikasi Data Statistik Sektoral | D7: Terkena serangan web defacement | E7: Konfigurasi default | F7: Insiden Web Defacement | G7: Aplikasi tidak dapat diakses | H7: Operasional dan Aset TIK | I7: Belum ada | J7: Signifikan | K7: Sering Terjadi | L7: =INDEX(RiskMatrix,MATCH(K7,RangeKemungkinan,0),MATCH(J7,RangeDampak,0)) -> 19 | M7: =INDEX(RiskLevel,MATCH(K7,RangeKemungkinan,0),MATCH(J7,RangeDampak,0)) -> Tinggi | N7: Ya | O7: 1 | P7: Mitigasi Risiko | Q7: Melakukan update konfigurasi sistem | R7: Sistem terupdate | S7: Agustus 2025 | T7: Kepala Bidang TIK | U7: Ya | V7: Cukup Signifikan | W7: Kadang-Kadang Terjadi | X7: =IF(U7="Ya",(INDEX(RiskMatrix,MATCH(W7,RangeKemungkinan,0),MATCH(V7,RangeDampak,0))),"N/A") -> 14 | Y7: =IF(ISNUMBER(X7),IF(X7>=11,"Not Acceptable","Acceptable"),"N/A") -> Not Acceptable | Z7: Melakukan uji keamanan sistem secara berkala | AA7: Diskominfo | AB7: =IF(Y7="Acceptable",1,0) -> 0 | AC7: =IF(Y7="Not Acceptable",1,0) -> 1 | AF7: =IF(ISNUMBER(L7),IF(L7>=11,"Not Acceptable","Acceptable"),"N/A") -> Not Acceptable | AG7: =IF(AF7="Acceptable",1,0) -> 0 | AH7: =IF(AF7="Not Acceptable",1,0) -> 1
A8: PL-002 | J8: Kurang Signifikan | K8: Hampir Tidak Terjadi | L8: =INDEX(RiskMatrix,MATCH(K8,RangeKemungkinan,0),MATCH(J8,RangeDampak,0)) -> 3 | M8: =INDEX(RiskLevel,MATCH(K8,RangeKemungkinan,0),MATCH(J8,RangeDampak,0)) -> Rendah | X8: =IF(U8="Ya",(INDEX(RiskMatrix,MATCH(W8,RangeKemungkinan,0),MATCH(V8,RangeDampak,0))),"N/A") -> N/A | Y8: =IF(ISNUMBER(X8),IF(X8>=11,"Not Acceptable","Acceptable"),"N/A") -> N/A | AB8: =IF(Y8="Acceptable",1,0) -> 0 | AC8: =IF(Y8="Not Acceptable",1,0) -> 0 | AF8: =IF(ISNUMBER(L8),IF(L8>=11,"Not Acceptable","Acceptable"),"N/A") -> Acceptable | AG8: =IF(AF8="Acceptable",1,0) -> 1 | AH8: =IF(AF8="Not Acceptable",1,0) -> 0
A9: PL-003 | L9: =INDEX(RiskMatrix,MATCH(K9,RangeKemungkinan,0),MATCH(J9,RangeDampak,0)) -> #N/A | M9: =INDEX(RiskLevel,MATCH(K9,RangeKemungkinan,0),MATCH(J9,RangeDampak,0)) -> #N/A | X9: =IF(U9="Ya",(INDEX(RiskMatrix,MATCH(W9,RangeKemungkinan,0),MATCH(V9,RangeDampak,0))),"N/A") -> N/A | Y9: =IF(ISNUMBER(X9),IF(X9>=11,"Not Acceptable","Acceptable"),"N/A") -> N/A | AB9: =IF(Y9="Acceptable",1,0) -> 0 | AC9: =IF(Y9="Not Acceptable",1,0) -> 0 | AF9: =IF(ISNUMBER(L9),IF(L9>=11,"Not Acceptable","Acceptable"),"N/A") -> N/A | AG9: =IF(AF9="Acceptable",1,0) -> 0 | AH9: =IF(AF9="Not Acceptable",1,0) -> 0
A10: PL-004 | L10: =INDEX(RiskMatrix,MATCH(K10,RangeKemungkinan,0),MATCH(J10,RangeDampak,0)) -> #N/A | M10: =INDEX(RiskLevel,MATCH(K10,RangeKemungkinan,0),MATCH(J10,RangeDampak,0)) -> #N/A | X10: =IF(U10="Ya",(INDEX(RiskMatrix,MATCH(W10,RangeKemungkinan,0),MATCH(V10,RangeDampak,0))),"N/A") -> N/A | Y10: =IF(ISNUMBER(X10),IF(X10>=11,"Not Acceptable","Acceptable"),"N/A") -> N/A | AB10: =IF(Y10="Acceptable",1,0) -> 0 | AC10: =IF(Y10="Not Acceptable",1,0) -> 0 | AF10: =IF(ISNUMBER(L10),IF(L10>=11,"Not Acceptable","Acceptable"),"N/A") -> N/A | AG10: =IF(AF10="Acceptable",1,0) -> 0 | AH10: =IF(AF10="Not Acceptable",1,0) -> 0
A11: PL-005 | L11: =INDEX(RiskMatrix,MATCH(K11,RangeKemungkinan,0),MATCH(J11,RangeDampak,0)) -> #N/A | M11: =INDEX(RiskLevel,MATCH(K11,RangeKemungkinan,0),MATCH(J11,RangeDampak,0)) -> #N/A | X11: =IF(U11="Ya",(INDEX(RiskMatrix,MATCH(W11,RangeKemungkinan,0),MATCH(V11,RangeDampak,0))),"N/A") -> N/A | Y11: =IF(ISNUMBER(X11),IF(X11>=11,"Not Acceptable","Acceptable"),"N/A") -> N/A | AB11: =IF(Y11="Acceptable",1,0) -> 0 | AC11: =IF(Y11="Not Acceptable",1,0) -> 0 | AF11: =IF(ISNUMBER(L11),IF(L11>=11,"Not Acceptable","Acceptable"),"N/A") -> N/A | AG11: =IF(AF11="Acceptable",1,0) -> 0 | AH11: =IF(AF11="Not Acceptable",1,0) -> 0
AB12: =SUM(AB7:AB11) -> 0 | AC12: =SUM(AC7:AC11) -> 1 | AG12: =SUM(AG7:AG11) -> 1 | AH12: =SUM(AH7:AH11) -> 1 | AI12: =SUM(AG12:AH12) -> 2

Sheet Perangkat Keras
D2: REGISTER RISIKO KEAMANAN INFORMASI (ASET: PERANGKAT KERAS) | V2: Revisi | Y2: Tanggal: | Z2: Dokumen:
A4: Risk No | B4: Jenis Risiko | C4: Identifikasi Resiko | I4: Kontrol Saat Ini | J4: Nilai Resiko Bawaan (Inherent Risk) | N4: EVALUASI RISIKO | P4: RENCANA PENANGANAN RISIKO | V4: Residual Risk | Z4: Rencana Kontrol Tambahan | AA4: Risk Owner
C5: Aset | D5: Ancaman | E5: Kerawanan/Kelemahan | F5: Kategori | G5: Dampak | H5: Area Dampak | N5: Keputusan Penanganan Risiko | O5: Prioritas Risiko | P5: Opsi Penanganan | Q5: Rencana Aksi Penanganan Risiko | R5: Keluaran | S5: Target/Jadwal Implementasi | T5: Penanggung Jawab | U5: Apakah Terdapat Residual Risk | V5: Dampak | W5: Kemungkinan | X5: RR | Y5: Status | AB5: Residual
J6: Dampak | K6: Kemungkinan | L6: IR | M6: Level Risiko | AB6: Acc | AC6: Not | AF6: Status Inherent Risk | AG6: Acc | AH6: Not | AI6: sum
A7: PK-001 | B7: Negatif | C7: Server | D7: Server diakses oleh pihak yang tidak berwenang | E7: Belum ada pembatasan hak akses ke data center | F7: Kesalahan Pengelolaan Aset | G7: Server tidak dapat diakses | H7: Operasional dan Aset TIK | I7: Larangan / tata tertib data center | J7: Signifikan | K7: Jarang Terjadi | L7: =INDEX(RiskMatrix,MATCH(K7,RangeKemungkinan,0),MATCH(J7,RangeDampak,0)) -> 13 | M7: =INDEX(RiskLevel,MATCH(K7,RangeKemungkinan,0),MATCH(J7,RangeDampak,0)) -> Sedang | N7: Ya | O7: 1 | P7: Mitigasi Risiko | Q7: Memasang kunci berbasis fingerprint | R7: Terpasangnya kunci berbasis fingerprint di data center | S7: Triwulan I Tahun 2026 | T7: Kepala Bidang TIK | U7: Ya | V7: Kurang Signifikan | W7: Hampir Tidak Terjadi | X7: =IF(U7="Ya",(INDEX(RiskMatrix,MATCH(W7,RangeKemungkinan,0),MATCH(V7,RangeDampak,0))),"N/A") -> 3 | Y7: =IF(ISNUMBER(X7),IF(X7>=11,"Not Acceptable","Acceptable"),"N/A") -> Acceptable | Z7: - | AA7: Diskominfo | AB7: =IF(Y7="Acceptable",1,0) -> 1 | AC7: =IF(Y7="Not Acceptable",1,0) -> 0 | AF7: =IF(ISNUMBER(L7),IF(L7>=11,"Not Acceptable","Acceptable"),"N/A") -> Not Acceptable | AG7: =IF(AF7="Acceptable",1,0) -> 0 | AH7: =IF(AF7="Not Acceptable",1,0) -> 1
A8: PK-002 | D8: Web Defacement | J8: Kurang Signifikan | K8: Hampir Tidak Terjadi | L8: =INDEX(RiskMatrix,MATCH(K8,RangeKemungkinan,0),MATCH(J8,RangeDampak,0)) -> 3 | M8: =INDEX(RiskLevel,MATCH(K8,RangeKemungkinan,0),MATCH(J8,RangeDampak,0)) -> Rendah | X8: =IF(U8="Ya",(INDEX(RiskMatrix,MATCH(W8,RangeKemungkinan,0),MATCH(V8,RangeDampak,0))),"N/A") -> N/A | Y8: =IF(ISNUMBER(X8),IF(X8>=11,"Not Acceptable","Acceptable"),"N/A") -> N/A | AB8: =IF(Y8="Acceptable",1,0) -> 0 | AC8: =IF(Y8="Not Acceptable",1,0) -> 0 | AF8: =IF(ISNUMBER(L8),IF(L8>=11,"Not Acceptable","Acceptable"),"N/A") -> Acceptable | AG8: =IF(AF8="Acceptable",1,0) -> 1 | AH8: =IF(AF8="Not Acceptable",1,0) -> 0
A9: PK-003 | L9: =INDEX(RiskMatrix,MATCH(K9,RangeKemungkinan,0),MATCH(J9,RangeDampak,0)) -> #N/A | M9: =INDEX(RiskLevel,MATCH(K9,RangeKemungkinan,0),MATCH(J9,RangeDampak,0)) -> #N/A | X9: =IF(U9="Ya",(INDEX(RiskMatrix,MATCH(W9,RangeKemungkinan,0),MATCH(V9,RangeDampak,0))),"N/A") -> N/A | Y9: =IF(ISNUMBER(X9),IF(X9>=11,"Not Acceptable","Acceptable"),"N/A") -> N/A | AB9: =IF(Y9="Acceptable",1,0) -> 0 | AC9: =IF(Y9="Not Acceptable",1,0) -> 0 | AF9: =IF(ISNUMBER(L9),IF(L9>=11,"Not Acceptable","Acceptable"),"N/A") -> N/A | AG9: =IF(AF9="Acceptable",1,0) -> 0 | AH9: =IF(AF9="Not Acceptable",1,0) -> 0
A10: PK-004 | L10: =INDEX(RiskMatrix,MATCH(K10,RangeKemungkinan,0),MATCH(J10,RangeDampak,0)) -> #N/A | M10: =INDEX(RiskLevel,MATCH(K10,RangeKemungkinan,0),MATCH(J10,RangeDampak,0)) -> #N/A | X10: =IF(U10="Ya",(INDEX(RiskMatrix,MATCH(W10,RangeKemungkinan,0),MATCH(V10,RangeDampak,0))),"N/A") -> N/A | Y10: =IF(ISNUMBER(X10),IF(X10>=11,"Not Acceptable","Acceptable"),"N/A") -> N/A | AB10: =IF(Y10="Acceptable",1,0) -> 0 | AC10: =IF(Y10="Not Acceptable",1,0) -> 0 | AF10: =IF(ISNUMBER(L10),IF(L10>=11,"Not Acceptable","Acceptable"),"N/A") -> N/A | AG10: =IF(AF10="Acceptable",1,0) -> 0 | AH10: =IF(AF10="Not Acceptable",1,0) -> 0
A11: PK-005 | L11: =INDEX(RiskMatrix,MATCH(K11,RangeKemungkinan,0),MATCH(J11,RangeDampak,0)) -> #N/A | M11: =INDEX(RiskLevel,MATCH(K11,RangeKemungkinan,0),MATCH(J11,RangeDampak,0)) -> #N/A | X11: =IF(U11="Ya",(INDEX(RiskMatrix,MATCH(W11,RangeKemungkinan,0),MATCH(V11,RangeDampak,0))),"N/A") -> N/A | Y11: =IF(ISNUMBER(X11),IF(X11>=11,"Not Acceptable","Acceptable"),"N/A") -> N/A | AB11: =IF(Y11="Acceptable",1,0) -> 0 | AC11: =IF(Y11="Not Acceptable",1,0) -> 0 | AF11: =IF(ISNUMBER(L11),IF(L11>=11,"Not Acceptable","Acceptable"),"N/A") -> N/A | AG11: =IF(AF11="Acceptable",1,0) -> 0 | AH11: =IF(AF11="Not Acceptable",1,0) -> 0
AB12: =SUM(AB7:AB11) -> 1 | AC12: =SUM(AC7:AC11) -> 0 | AG12: =SUM(AG7:AG11) -> 1 | AH12: =SUM(AH7:AH11) -> 1 | AI12: =SUM(AG12:AH12) -> 2

Sheet Sarana Pendukung
D2: REGISTER RISIKO KEAMANAN INFORMASI (ASET: SARANA PENDUKUNG) | V2: Revisi | Y2: Tanggal: | Z2: Dokumen:
A4: Risk No | B4: Jenis Risiko | C4: Identifikasi Resiko | I4: Kontrol Saat Ini | J4: Nilai Resiko Bawaan (Inherent Risk) | N4: EVALUASI RISIKO | P4: RENCANA PENANGANAN RISIKO | V4: Residual Risk | Z4: Rencana Kontrol Tambahan | AA4: Risk Owner
C5: Aset | D5: Ancaman | E5: Kerawanan/Kelemahan | F5: Kategori | G5: Dampak | H5: Area Dampak | N5: Keputusan Penanganan Risiko | O5: Prioritas Risiko | P5: Opsi Penanganan | Q5: Rencana Aksi Penanganan Risiko | R5: Keluaran | S5: Target/Jadwal Implementasi | T5: Penanggung Jawab | U5: Apakah Terdapat Residual Risk | V5: Dampak | W5: Kemungkinan | X5: RR | Y5: Status | AB5: Residual
J6: Dampak | K6: Kemungkinan | L6: IR | M6: Level Risiko | AB6: Acc | AC6: Not | AF6: Status Inherent Risk | AG6: Acc | AH6: Not | AI6: sum
A7: SP-001 | C7: AC | J7: Signifikan | K7: Sering Terjadi | L7: =INDEX(RiskMatrix,MATCH(K7,RangeKemungkinan,0),MATCH(J7,RangeDampak,0)) -> 19 | M7: =INDEX(RiskLevel,MATCH(K7,RangeKemungkinan,0),MATCH(J7,RangeDampak,0)) -> Tinggi | U7: Ya | V7: Kurang Signifikan | W7: Jarang Terjadi | X7: =IF(U7="Ya",(INDEX(RiskMatrix,MATCH(W7,RangeKemungkinan,0),MATCH(V7,RangeDampak,0))),"N/A") -> 7 | Y7: =IF(ISNUMBER(X7),IF(X7>=11,"Not Acceptable","Acceptable"),"N/A") -> Acceptable | AB7: =IF(Y7="Acceptable",1,0) -> 1 | AC7: =IF(Y7="Not Acceptable",1,0) -> 0 | AF7: =IF(ISNUMBER(L7),IF(L7>=11,"Not Acceptable","Acceptable"),"N/A") -> Not Acceptable | AG7: =IF(AF7="Acceptable",1,0) -> 0 | AH7: =IF(AF7="Not Acceptable",1,0) -> 1
A8: SP-002 | C8: APAR | J8: Kurang Signifikan | K8: Hampir Tidak Terjadi | L8: =INDEX(RiskMatrix,MATCH(K8,RangeKemungkinan,0),MATCH(J8,RangeDampak,0)) -> 3 | M8: =INDEX(RiskLevel,MATCH(K8,RangeKemungkinan,0),MATCH(J8,RangeDampak,0)) -> Rendah | X8: =IF(U8="Ya",(INDEX(RiskMatrix,MATCH(W8,RangeKemungkinan,0),MATCH(V8,RangeDampak,0))),"N/A") -> N/A | Y8: =IF(ISNUMBER(X8),IF(X8>=11,"Not Acceptable","Acceptable"),"N/A") -> N/A | AB8: =IF(Y8="Acceptable",1,0) -> 0 | AC8: =IF(Y8="Not Acceptable",1,0) -> 0 | AF8: =IF(ISNUMBER(L8),IF(L8>=11,"Not Acceptable","Acceptable"),"N/A") -> Acceptable | AG8: =IF(AF8="Acceptable",1,0) -> 1 | AH8: =IF(AF8="Not Acceptable",1,0) -> 0
A9: SP-003 | C9: Sensor Asap | L9: =INDEX(RiskMatrix,MATCH(K9,RangeKemungkinan,0),MATCH(J9,RangeDampak,0)) -> #N/A | M9: =INDEX(RiskLevel,MATCH(K9,RangeKemungkinan,0),MATCH(J9,RangeDampak,0)) -> #N/A | X9: =IF(U9="Ya",(INDEX(RiskMatrix,MATCH(W9,RangeKemungkinan,0),MATCH(V9,RangeDampak,0))),"N/A") -> N/A | Y9: =IF(ISNUMBER(X9),IF(X9>=11,"Not Acceptable","Acceptable"),"N/A") -> N/A | AB9: =IF(Y9="Acceptable",1,0) -> 0 | AC9: =IF(Y9="Not Acceptable",1,0) -> 0 | AF9: =IF(ISNUMBER(L9),IF(L9>=11,"Not Acceptable","Acceptable"),"N/A") -> N/A | AG9: =IF(AF9="Acceptable",1,0) -> 0 | AH9: =IF(AF9="Not Acceptable",1,0) -> 0
A10: SP-004 | L10: =INDEX(RiskMatrix,MATCH(K10,RangeKemungkinan,0),MATCH(J10,RangeDampak,0)) -> #N/A | M10: =INDEX(RiskLevel,MATCH(K10,RangeKemungkinan,0),MATCH(J10,RangeDampak,0)) -> #N/A | X10: =IF(U10="Ya",(INDEX(RiskMatrix,MATCH(W10,RangeKemungkinan,0),MATCH(V10,RangeDampak,0))),"N/A") -> N/A | Y10: =IF(ISNUMBER(X10),IF(X10>=11,"Not Acceptable","Acceptable"),"N/A") -> N/A | AB10: =IF(Y10="Acceptable",1,0) -> 0 | AC10: =IF(Y10="Not Acceptable",1,0) -> 0 | AF10: =IF(ISNUMBER(L10),IF(L10>=11,"Not Acceptable","Acceptable"),"N/A") -> N/A | AG10: =IF(AF10="Acceptable",1,0) -> 0 | AH10: =IF(AF10="Not Acceptable",1,0) -> 0
A11: SP-005 | L11: =INDEX(RiskMatrix,MATCH(K11,RangeKemungkinan,0),MATCH(J11,RangeDampak,0)) -> #N/A | M11: =INDEX(RiskLevel,MATCH(K11,RangeKemungkinan,0),MATCH(J11,RangeDampak,0)) -> #N/A | X11: =IF(U11="Ya",(INDEX(RiskMatrix,MATCH(W11,RangeKemungkinan,0),MATCH(V11,RangeDampak,0))),"N/A") -> N/A | Y11: =IF(ISNUMBER(X11),IF(X11>=11,"Not Acceptable","Acceptable"),"N/A") -> N/A | AB11: =IF(Y11="Acceptable",1,0) -> 0 | AC11: =IF(Y11="Not Acceptable",1,0) -> 0 | AF11: =IF(ISNUMBER(L11),IF(L11>=11,"Not Acceptable","Acceptable"),"N/A") -> N/A | AG11: =IF(AF11="Acceptable",1,0) -> 0 | AH11: =IF(AF11="Not Acceptable",1,0) -> 0
AB12: =SUM(AB7:AB11) -> 1 | AC12: =SUM(AC7:AC11) -> 0 | AG12: =SUM(AG7:AG11) -> 1 | AH12: =SUM(AH7:AH11) -> 1 | AI12: =SUM(AG12:AH12) -> 2

Sheet SDM & Pihak Ketiga
D2: REGISTER RISIKO KEAMANAN INFORMASI (ASET: SDM & PIHAK KETIGA) | V2: Revisi | Y2: Tanggal: | Z2: Dokumen:
A4: Risk No | B4: Jenis Risiko | C4: Identifikasi Resiko | I4: Kontrol Saat Ini | J4: Nilai Resiko Bawaan (Inherent Risk) | N4: EVALUASI RISIKO | P4: RENCANA PENANGANAN RISIKO | V4: Residual Risk | Z4: Rencana Kontrol Tambahan | AA4: Risk Owner
C5: Aset | D5: Ancaman | E5: Kerawanan/Kelemahan | F5: Kategori | G5: Dampak | H5: Area Dampak | N5: Keputusan Penanganan Risiko | O5: Prioritas Risiko | P5: Opsi Penanganan | Q5: Rencana Aksi Penanganan Risiko | R5: Keluaran | S5: Target/Jadwal Implementasi | T5: Penanggung Jawab | U5: Apakah Terdapat Residual Risk | V5: Dampak | W5: Kemungkinan | X5: RR | Y5: Status | AB5: Residual
J6: Dampak | K6: Kemungkinan | L6: IR | M6: Level Risiko | AB6: Acc | AC6: Not | AF6: Status Inherent Risk | AG6: Acc | AH6: Not | AI6: sum
A7: PS-001 | B7: Negatif | C7: Pihak Ketiga | D7: Pihak Ketiga membocorkan informasi | E7: Tidak ada perjanjian kerahasiaan | F7: Kesalahan Pengelolaan oleh Pihak Ketiga | J7: Signifikan | K7: Sering Terjadi | L7: =INDEX(RiskMatrix,MATCH(K7,RangeKemungkinan,0),MATCH(J7,RangeDampak,0)) -> 19 | M7: =INDEX(RiskLevel,MATCH(K7,RangeKemungkinan,0),MATCH(J7,RangeDampak,0)) -> Tinggi | U7: Ya | V7: Kurang Signifikan | W7: Jarang Terjadi | X7: =IF(U7="Ya",(INDEX(RiskMatrix,MATCH(W7,RangeKemungkinan,0),MATCH(V7,RangeDampak,0))),"N/A") -> 7 | Y7: =IF(ISNUMBER(X7),IF(X7>=11,"Not Acceptable","Acceptable"),"N/A") -> Acceptable | AB7: =IF(Y7="Acceptable",1,0) -> 1 | AC7: =IF(Y7="Not Acceptable",1,0) -> 0 | AF7: =IF(ISNUMBER(L7),IF(L7>=11,"Not Acceptable","Acceptable"),"N/A") -> Not Acceptable | AG7: =IF(AF7="Acceptable",1,0) -> 0 | AH7: =IF(AF7="Not Acceptable",1,0) -> 1
A8: PS-002 | J8: Kurang Signifikan | K8: Hampir Tidak Terjadi | L8: =INDEX(RiskMatrix,MATCH(K8,RangeKemungkinan,0),MATCH(J8,RangeDampak,0)) -> 3 | M8: =INDEX(RiskLevel,MATCH(K8,RangeKemungkinan,0),MATCH(J8,RangeDampak,0)) -> Rendah | X8: =IF(U8="Ya",(INDEX(RiskMatrix,MATCH(W8,RangeKemungkinan,0),MATCH(V8,RangeDampak,0))),"N/A") -> N/A | Y8: =IF(ISNUMBER(X8),IF(X8>=11,"Not Acceptable","Acceptable"),"N/A") -> N/A | AB8: =IF(Y8="Acceptable",1,0) -> 0 | AC8: =IF(Y8="Not Acceptable",1,0) -> 0 | AF8: =IF(ISNUMBER(L8),IF(L8>=11,"Not Acceptable","Acceptable"),"N/A") -> Acceptable | AG8: =IF(AF8="Acceptable",1,0) -> 1 | AH8: =IF(AF8="Not Acceptable",1,0) -> 0
A9: PS-003 | L9: =INDEX(RiskMatrix,MATCH(K9,RangeKemungkinan,0),MATCH(J9,RangeDampak,0)) -> #N/A | M9: =INDEX(RiskLevel,MATCH(K9,RangeKemungkinan,0),MATCH(J9,RangeDampak,0)) -> #N/A | X9: =IF(U9="Ya",(INDEX(RiskMatrix,MATCH(W9,RangeKemungkinan,0),MATCH(V9,RangeDampak,0))),"N/A") -> N/A | Y9: =IF(ISNUMBER(X9),IF(X9>=11,"Not Acceptable","Acceptable"),"N/A") -> N/A | AB9: =IF(Y9="Acceptable",1,0) -> 0 | AC9: =IF(Y9="Not Acceptable",1,0) -> 0 | AF9: =IF(ISNUMBER(L9),IF(L9>=11,"Not Acceptable","Acceptable"),"N/A") -> N/A | AG9: =IF(AF9="Acceptable",1,0) -> 0 | AH9: =IF(AF9="Not Acceptable",1,0) -> 0
A10: PS-004 | L10: =INDEX(RiskMatrix,MATCH(K10,RangeKemungkinan,0),MATCH(J10,RangeDampak,0)) -> #N/A | M10: =INDEX(RiskLevel,MATCH(K10,RangeKemungkinan,0),MATCH(J10,RangeDampak,0)) -> #N/A | X10: =IF(U10="Ya",(INDEX(RiskMatrix,MATCH(W10,RangeKemungkinan,0),MATCH(V10,RangeDampak,0))),"N/A") -> N/A | Y10: =IF(ISNUMBER(X10),IF(X10>=11,"Not Acceptable","Acceptable"),"N/A") -> N/A | AB10: =IF(Y10="Acceptable",1,0) -> 0 | AC10: =IF(Y10="Not Acceptable",1,0) -> 0 | AF10: =IF(ISNUMBER(L10),IF(L10>=11,"Not Acceptable","Acceptable"),"N/A") -> N/A | AG10: =IF(AF10="Acceptable",1,0) -> 0 | AH10: =IF(AF10="Not Acceptable",1,0) -> 0
A11: PS-005 | L11: =INDEX(RiskMatrix,MATCH(K11,RangeKemungkinan,0),MATCH(J11,RangeDampak,0)) -> #N/A | M11: =INDEX(RiskLevel,MATCH(K11,RangeKemungkinan,0),MATCH(J11,RangeDampak,0)) -> #N/A | X11: =IF(U11="Ya",(INDEX(RiskMatrix,MATCH(W11,RangeKemungkinan,0),MATCH(V11,RangeDampak,0))),"N/A") -> N/A | Y11: =IF(ISNUMBER(X11),IF(X11>=11,"Not Acceptable","Acceptable"),"N/A") -> N/A | AB11: =IF(Y11="Acceptable",1,0) -> 0 | AC11: =IF(Y11="Not Acceptable",1,0) -> 0 | AF11: =IF(ISNUMBER(L11),IF(L11>=11,"Not Acceptable","Acceptable"),"N/A") -> N/A | AG11: =IF(AF11="Acceptable",1,0) -> 0 | AH11: =IF(AF11="Not Acceptable",1,0) -> 0
AB12: =SUM(AB7:AB11) -> 1 | AC12: =SUM(AC7:AC11) -> 0 | AG12: =SUM(AG7:AG11) -> 1 | AH12: =SUM(AH7:AH11) -> 1 | AI12: =SUM(AG12:AH12) -> 2

Sheet Peta Risiko
C3: Matriks Analisis Risiko 5X5 | F3: Level Dampak
F4: 1 | G4: 2 | H4: 3 | I4: 4 | J4: 5
F5: Tidak Signifikan | G5: Kurang Signifikan | H5: Cukup Signifikan | I5: Signifikan | J5: Sangat Signifikan
C6: Level Kemungkinan | D6: 1 | E6: Hampir Tidak Terjadi | F6: 1 | G6: 3 | H6: 5 | I6: 8 | J6: 20
D7: 2 | E7: Jarang Terjadi | F7: 2 | G7: 7 | H7: 11 | I7: 13 | J7: 21
D8: 3 | E8: Kadang-Kadang Terjadi | F8: 4 | G8: 10 | H8: 14 | I8: 17 | J8: 22
D9: 4 | E9: Sering Terjadi | F9: 6 | G9: 12 | H9: 16 | I9: 19 | J9: 24
D10: 5 | E10: Hampir Pasti Terjadi | F10: 9 | G10: 15 | H10: 18 | I10: 23 | J10: 25
C12: Matriks Analisis Risiko 5X5 | F12: Level Dampak
F13: 1 | G13: 2 | H13: 3 | I13: 4 | J13: 5
F14: Tidak Signifikan | G14: Kurang Signifikan | H14: Cukup Signifikan | I14: Signifikan | J14: Sangat Signifikan
C15: Level Kemungkinan | D15: 1 | E15: Hampir Tidak Terjadi | F15: Sangat Rendah | G15: Rendah | H15: Sedang | I15: Sedang | J15: Tinggi
D16: 2 | E16: Jarang Terjadi | F16: Sangat Rendah | G16: Rendah | H16: Sedang | I16: Sedang | J16: Sangat Tinggi
D17: 3 | E17: Kadang-Kadang Terjadi | F17: Sangat Rendah | G17: Rendah | H17: Sedang | I17: Tinggi | J17: Sangat Tinggi
D18: 4 | E18: Sering Terjadi | F18: Rendah | G18: Sedang | H18: Tinggi | I18: Tinggi | J18: Sangat Tinggi
D19: 5 | E19: Hampir Pasti Terjadi | F19: Rendah | G19: Sedang | H19: Tinggi | I19: Sangat Tinggi | J19: Sangat Tinggi
C21: Level Risiko | G21: Rentang Besaran Risiko | I21: Keterangan Warna
C22: 1 | D22: Sangat Rendah | G22: 1-5
C23: 2 | D23: Rendah | G23: 6-10
C24: 3 | D24: Sedang | G24: 11-15
C25: 4 | D25: Tinggi | G25: 16-20
C26: 5 | D26: Sangat Tinggi | G26: 21-25
C28: Kemungkinan | F28: Terjadinya Dalam 1 Periode
C29: 1 | D29: Hampir Tidak Terjadi | F29: x<= 5% | H29: < 2 kali dalam 1 tahun
C30: 2 | D30: Jarang Terjadi | F30: 5%<x<=10% | H30: 2-5 kali dalam 1 tahun
C31: 3 | D31: Kadang-Kadang Terjadi | F31: 10%<x<=20% | H31: 6-9 kali dalam 1 tahun
C32: 4 | D32: Sering Terjadi | F32: 20%<x<=50% | H32: 10-12 kali dalam 1 tahun
C33: 5 | D33: Hampir Pasti Terjadi | F33: x>50% | H33: > 12 kali dalam 1 tahun
C35: Dampak | F35: Finansial | H35: Reputasi | J35: Kinerja | L35: Layanan Organisasi | N35: Operasional TIK | P35: Hukum dan Regulasi | R35: SDM | T35: Uraian Tambahan jika dibutuhkan
C36: 1 | D36: Tidak Signifikan | F36: Jumlah kerugian negara ≤ Rp 10 juta | H36: Keluhan stakeholder secara langsung lisan/ tertulis jumlahnya ≤ 3 kali dalam satu periode | J36: Penurunan <20% | L36: Business Process tertunda ≤ 1 hari | N36: Gangguan kecil | P36: Tidak ada pelanggaran hukum | R36: N/A
C37: 2 | D37: Kurang Signifikan | F37: umlah kerugian negara lebih dari Rp 10 juta s.d Rp 50 juta | H37: Keluhan stakeholder secara langsung lisan/ tertulis ke organisasi jumlahnya lebih dari 3 kali dalam satu periode | J37: Penurunan 20%<x<=40% | L37: Business Process tertunda di atas 1 hari s.d. 5 hari | N37: Gangguan sporadis | P37: Pelanggaran ringan dengan teguran | R37: N/A
C38: 3 | D38: Cukup Signifikan | F38: Jumlah kerugian negara lebih dari Rp 50 juta s.d Rp 100 juta | H38: Pemberitaan negatif di dalam media massa lokal | J38: Penurunan 40%<x<=60% | L38: Business Process tertunda di atas 5 hari s.d. 15 hari | N38: Terhenti sementara | P38: Pelanggaran ringan dengan surat peringatan | R38: N/A
C39: 4 | D39: Signifikan | F39: Jumlah kerugian negara lebih dari Rp 100 juta s.d Rp 500 juta | H39: Pemberitaan negatif di dalam media massa nasional | J39: Penurunan 60%<x<=80% | L39: Business Process tertunda di atas 15 hari s.d. 30 hari | N39: Terhenti lama | P39: Pelanggaran sedang yang dikenakan sanksi administratif | R39: N/A
C40: 5 | D40: Sangat Signifikan | F40: Jumlah kerugian negara lebih Rp 500 juta | H40: Pemberitaan negatif di dalam media massa internasional | J40: Penurunan >80% | L40: Business Process tertunda di atas 30 hari | N40: Tidak berfungsi | P40: Pelanggaran berat dengan sanksi hukum | R40: N/A

Sheet List Kategori Risiko Keamanan
A1: Kategori Risiko Keamanan SPBE
A2: Penyalahgunaan Kontrol Akses
A3: Pencurian Data Pribadi
A4: Insiden Web Defacement
A5: Keamanan Cloud Service
A6: Keamanan Infrastruktur
A7: Ketidaksesuaian Pengelolaan Aplikasi
A8: Kesalahan Pengelolaan Data dan Informasi Terbatas
A9: Kesalahan Pengelolaan SDM
A10: Kesalahan Pengelolaan Aset
A11: Kesalahan Pengelolaan oleh Pihak Ketiga
A12: Terganggunya Keberlangsungan Layanan
A13: Insiden Serangan Malware

Sheet List Ancaman dan Kerentanan
A1: Aset | B1: Ancaman | C1: Kerentanan
A2: Perangkat Keras | B2: Server secara logikal dapat diakses oleh pihak yang tidak berwenang | C2: Tidak adanya prosedur yang mengatur pengaksesan server secara logikal sesuai dengan wewenang dan privilege personil
C3: Password tidak pernah diganti secara berkala
C4: Tidak menerapkan sistem keamanan pada server
C5: Belum ada penerapan segmentasi jaringan
C6: VPN belum terintegrasi dengan active directory
B7: Server secara fisikal dapat diakses oleh pihak yang tidak berwenang | C7: Tidak adanya prosedur yang mengatur pengaksesan server secara fisikal sesuai dengan wewenang dan privilege personil
C8: Tidak menerapkan sistem keamanan fisik pada server
C9: Pengawasan akses fisik oleh pihak berwenang kurang optimal
C10: Akses keluar masuk ruang server tidak terkendali dan terdokumentasikan dengan baik
C11: Rak server tidak dikunci
C12: Tidak adanya mekanisme terpusat untuk monitoring penggunaan user dalam mengakses server
C13: Tidak optimalnya manajemen log akses server
B14: Terjadi peretasan pada server | C14: Server dapat disusupi backdoor
C15: Kurangnya security awareness pengguna server
C16: Manajemen password yang buruk
C17: Tidak ada anti malware atau antivirus
C18: OS server tidak up-to-date
C19: Aplikasi yang terdapat pada server tidak up-to-date
C20: Pelaksanaan Vulnerability Assessment tidak dilakukan secara berkala
C21: Firewall tidak diaktifkan
C22: Masih terdapat port terbuka yang tidak digunakan
B23: Kerusakan pada server | C23: Kurangnya mekanisme pemeliharaan terhadap server
C24: Listrik tidak stabil / sering mengalami pemadaman listrik
B25: Kapasitas server melebihi batas | C25: Kurangnya monitoring terhadap kapasitas penggunaan server serta pembaharuan kebutuhan kapastitas server
B26: Kegagalan fungsi server | C26: Kurangnya monitoring, pengujian dan pemeliharaan server
C27: Server kekurangan daya
C28: Perubahan konfigurasi sistem pada server tidak terkelola dengan baik
C29: Tidak adanya proses change management
C30: Kesalahan operasional (pencabutan dan penyambungan kabel) akibat penataan kabel yang tidak rapih
C31: Lingkungan ruang server tidak dimonitor secara berkala (debu, suhu, dan kelembaban)
B32: PC/ Laptop digunakan oleh pihak yang tidak berwenang | C32: Kurangnya security awareness pengguna PC/laptop
C33: Tidak ada pengaturan pembatasan penggunaan PC / laptop
C34: Tidak ada penerapan sistem keamanan pada PC / laptop
C35: Tidak berjalannya prosedur pengamanan yang sudah ada
C36: Pengelolaan pengguna dan password PC & laptop belum dilakukan secara terpadu
B37: PC / Laptop terkena malicious code | C37: Tidak adanya antivirus yang digunakan
C38: Aplikasi dan/atau OS pada PC/laptop tidak up-to-date
B39: Kerusakan PC/Laptop | C39: Kelalaian pengguna PC/laptop
C40: Kurangnya maintenance terhadap PC/laptop
...
